[2023-07-29T22:48:06.961+0000] {taskinstance.py:1103} INFO - Dependencies all met for dep_context=non-requeueable deps ti=<TaskInstance: trainer.encrypt_data_worker2 manual__2023-07-29T22:26:04.728771+00:00 [queued]>
[2023-07-29T22:48:06.968+0000] {taskinstance.py:1103} INFO - Dependencies all met for dep_context=requeueable deps ti=<TaskInstance: trainer.encrypt_data_worker2 manual__2023-07-29T22:26:04.728771+00:00 [queued]>
[2023-07-29T22:48:06.969+0000] {taskinstance.py:1308} INFO - Starting attempt 4 of 4
[2023-07-29T22:48:06.979+0000] {taskinstance.py:1327} INFO - Executing <Task(BranchPythonOperator): encrypt_data_worker2> on 2023-07-29 22:26:04.728771+00:00
[2023-07-29T22:48:06.990+0000] {standard_task_runner.py:57} INFO - Started process 555678 to run task
[2023-07-29T22:48:06.992+0000] {standard_task_runner.py:84} INFO - Running: ['airflow', 'tasks', 'run', 'trainer', 'encrypt_data_worker2', 'manual__2023-07-29T22:26:04.728771+00:00', '--job-id', '17', '--raw', '--subdir', 'DAGS_FOLDER/train_dag.py', '--cfg-path', '/tmp/tmpxj8y0n9g']
[2023-07-29T22:48:06.992+0000] {standard_task_runner.py:85} INFO - Job 17: Subtask encrypt_data_worker2
[2023-07-29T22:48:07.042+0000] {task_command.py:410} INFO - Running <TaskInstance: trainer.encrypt_data_worker2 manual__2023-07-29T22:26:04.728771+00:00 [running]> on host ip-172-31-37-30.ap-south-1.compute.internal
[2023-07-29T22:48:07.117+0000] {taskinstance.py:1545} INFO - Exporting env vars: AIRFLOW_CTX_DAG_OWNER='airflow' AIRFLOW_CTX_DAG_ID='trainer' AIRFLOW_CTX_TASK_ID='encrypt_data_worker2' AIRFLOW_CTX_EXECUTION_DATE='2023-07-29T22:26:04.728771+00:00' AIRFLOW_CTX_TRY_NUMBER='4' AIRFLOW_CTX_DAG_RUN_ID='manual__2023-07-29T22:26:04.728771+00:00'
[2023-07-29T22:48:07.155+0000] {taskinstance.py:1824} ERROR - Task failed with exception
Traceback (most recent call last):
  File "/home/ubuntu/theft-detection/env1/lib/python3.10/site-packages/airflow/operators/python.py", line 215, in execute
    branch = super().execute(context)
  File "/home/ubuntu/theft-detection/env1/lib/python3.10/site-packages/airflow/operators/python.py", line 181, in execute
    return_value = self.execute_callable()
  File "/home/ubuntu/theft-detection/env1/lib/python3.10/site-packages/airflow/operators/python.py", line 198, in execute_callable
    return self.python_callable(*self.op_args, **self.op_kwargs)
  File "/home/ubuntu/GenAI-Rush/GenAI-Rush-FedGen/airflow/dags/train_dag.py", line 31, in encrypt_module
    processData.splitData()
  File "/home/ubuntu/GenAI-Rush/GenAI-Rush-FedGen/fedgen/fetchData.py", line 49, in splitData
    trainDf.to_csv(os.path.join(self.save_path, f'train_{self.worker}.csv'), index=None)
  File "/home/ubuntu/theft-detection/env1/lib/python3.10/site-packages/pandas/core/generic.py", line 3772, in to_csv
    return DataFrameRenderer(formatter).to_csv(
  File "/home/ubuntu/theft-detection/env1/lib/python3.10/site-packages/pandas/io/formats/format.py", line 1186, in to_csv
    csv_formatter.save()
  File "/home/ubuntu/theft-detection/env1/lib/python3.10/site-packages/pandas/io/formats/csvs.py", line 240, in save
    with get_handle(
  File "/home/ubuntu/theft-detection/env1/lib/python3.10/site-packages/pandas/io/common.py", line 737, in get_handle
    check_parent_directory(str(handle))
  File "/home/ubuntu/theft-detection/env1/lib/python3.10/site-packages/pandas/io/common.py", line 600, in check_parent_directory
    raise OSError(rf"Cannot save file into a non-existent directory: '{parent}'")
OSError: Cannot save file into a non-existent directory: '../processed'
[2023-07-29T22:48:07.167+0000] {taskinstance.py:1345} INFO - Marking task as FAILED. dag_id=trainer, task_id=encrypt_data_worker2, execution_date=20230729T222604, start_date=20230729T224806, end_date=20230729T224807
[2023-07-29T22:48:07.175+0000] {standard_task_runner.py:104} ERROR - Failed to execute job 17 for task encrypt_data_worker2 (Cannot save file into a non-existent directory: '../processed'; 555678)
[2023-07-29T22:48:07.204+0000] {local_task_job_runner.py:225} INFO - Task exited with return code 1
[2023-07-29T22:48:07.230+0000] {taskinstance.py:2653} INFO - 0 downstream tasks scheduled from follow-on schedule check
