[2023-07-29T22:26:10.008+0000] {taskinstance.py:1103} INFO - Dependencies all met for dep_context=non-requeueable deps ti=<TaskInstance: trainer.encrypt_data_worker2 manual__2023-07-29T22:26:04.728771+00:00 [queued]>
[2023-07-29T22:26:10.015+0000] {taskinstance.py:1103} INFO - Dependencies all met for dep_context=requeueable deps ti=<TaskInstance: trainer.encrypt_data_worker2 manual__2023-07-29T22:26:04.728771+00:00 [queued]>
[2023-07-29T22:26:10.015+0000] {taskinstance.py:1308} INFO - Starting attempt 1 of 1
[2023-07-29T22:26:10.026+0000] {taskinstance.py:1327} INFO - Executing <Task(BranchPythonOperator): encrypt_data_worker2> on 2023-07-29 22:26:04.728771+00:00
[2023-07-29T22:26:10.038+0000] {standard_task_runner.py:57} INFO - Started process 533424 to run task
[2023-07-29T22:26:10.041+0000] {standard_task_runner.py:84} INFO - Running: ['airflow', 'tasks', 'run', 'trainer', 'encrypt_data_worker2', 'manual__2023-07-29T22:26:04.728771+00:00', '--job-id', '6', '--raw', '--subdir', 'DAGS_FOLDER/train_dag.py', '--cfg-path', '/tmp/tmp7r163zhi']
[2023-07-29T22:26:10.041+0000] {standard_task_runner.py:85} INFO - Job 6: Subtask encrypt_data_worker2
[2023-07-29T22:26:10.094+0000] {task_command.py:410} INFO - Running <TaskInstance: trainer.encrypt_data_worker2 manual__2023-07-29T22:26:04.728771+00:00 [running]> on host ip-172-31-37-30.ap-south-1.compute.internal
[2023-07-29T22:26:10.179+0000] {taskinstance.py:1545} INFO - Exporting env vars: AIRFLOW_CTX_DAG_OWNER='airflow' AIRFLOW_CTX_DAG_ID='trainer' AIRFLOW_CTX_TASK_ID='encrypt_data_worker2' AIRFLOW_CTX_EXECUTION_DATE='2023-07-29T22:26:04.728771+00:00' AIRFLOW_CTX_TRY_NUMBER='1' AIRFLOW_CTX_DAG_RUN_ID='manual__2023-07-29T22:26:04.728771+00:00'
[2023-07-29T22:26:10.182+0000] {taskinstance.py:1824} ERROR - Task failed with exception
Traceback (most recent call last):
  File "/home/ubuntu/theft-detection/env1/lib/python3.10/site-packages/airflow/operators/python.py", line 215, in execute
    branch = super().execute(context)
  File "/home/ubuntu/theft-detection/env1/lib/python3.10/site-packages/airflow/operators/python.py", line 181, in execute
    return_value = self.execute_callable()
  File "/home/ubuntu/theft-detection/env1/lib/python3.10/site-packages/airflow/operators/python.py", line 198, in execute_callable
    return self.python_callable(*self.op_args, **self.op_kwargs)
  File "/home/ubuntu/GenAI-Rush/GenAI-Rush-FedGen/airflow/dags/train_dag.py", line 26, in encrypt_module
    config = json.load(file)['covid_radiography']
KeyError: 'covid_radiography'
[2023-07-29T22:26:10.194+0000] {taskinstance.py:1345} INFO - Marking task as FAILED. dag_id=trainer, task_id=encrypt_data_worker2, execution_date=20230729T222604, start_date=20230729T222610, end_date=20230729T222610
[2023-07-29T22:26:10.204+0000] {standard_task_runner.py:104} ERROR - Failed to execute job 6 for task encrypt_data_worker2 ('covid_radiography'; 533424)
[2023-07-29T22:26:10.253+0000] {local_task_job_runner.py:225} INFO - Task exited with return code 1
[2023-07-29T22:26:10.292+0000] {taskinstance.py:2653} INFO - 0 downstream tasks scheduled from follow-on schedule check
